Workbook

Sheet Model Architecture

Sheet Input | Output Embedding
B2: INPUT | OUTPUT SEQUENCE to INPUT | OUTPUT EMBEDDING
B3: INPUT | OUTPUT EMBEDDING (sequence, dmodel)
B5: INPUT SEQUENCE | D5: 0 | E5: 1 | F5: 2 | G5: 3 | H5: … | I5: 512
B6: Your | D6: {=M19:R24} -> 0.81509486 | E6: 0.55114382 | F6: 0.87599013 | G6: 0.9402011 | H6: 0.13961207 | I6: 0.50773764
B7: cat | D7: 0.55434696 | E7: 0.20676972 | F7: 0.28566684 | G7: 0.26753727 | H7: 0.96215895 | I7: 0.90933916
B8: is | D8: 0.92701969 | E8: 0.64751739 | F8: 0.97386071 | G8: 0.62071448 | H8: 0.10874277 | I8: 0.47095758
B9: a | D9: 0.46214985 | E9: 0.89997655 | F9: 0.7277061 | G9: 0.18032843 | H9: 0.26507507 | I9: 0.94154795
B10: lovely | D10: 0.29483136 | E10: 0.7624218 | F10: 0.98975632 | G10: 0.61433463 | H10: 0.40733789 | I10: 0.8128624
B11: cat | D11: 0.94494223 | E11: 0.56625407 | F11: 0.59216155 | G11: 0.61709469 | H11: 0.28425962 | I11: 0.68364143
B13: OUTPUT SEQUENCE | D13: 0 | E13: 1 | F13: 2 | G13: 3 | H13: … | I13: 512
B14: Ti | D14: {=V19:AA21} -> 0.87407494 | E14: 0.1616376 | F14: 0.13592546 | G14: 0.64719996 | H14: 0.61675058 | I14: 0.59749903
B15: amo | D15: 0.10054551 | E15: 0.5714363 | F15: 0.17186502 | G15: 0.50482714 | H15: 0.60754361 | I15: 0.40792812
B16: molto | D16: 0.50391991 | E16: 0.44164665 | F16: 0.21408732 | G16: 0.50996844 | H16: 0.52520804 | I16: 0.57030463
B17: <pad> | D17: -10000000000 | E17: -10000000000 | F17: -10000000000 | G17: -10000000000 | H17: -10000000000 | I17: -10000000000
B18: <pad> | D18: -10000000000 | E18: -10000000000 | F18: -10000000000 | G18: -10000000000 | H18: -10000000000 | I18: -10000000000 | K18: LOOKUP MATRIX | M18: 0 | N18: 1 | O18: 2 | P18: 3 | Q18: … | R18: 512 | T18: LOOKUP MATRIX | V18: 0 | W18: 1 | X18: 2 | Y18: 3 | Z18: … | AA18: 512
B19: <pad> | D19: -10000000000 | E19: -10000000000 | F19: -10000000000 | G19: -10000000000 | H19: -10000000000 | I19: -10000000000 | L19: Your | M19: {=_xlfn.RANDARRAY(9, 6, 0.1,1,FALSE)} -> 0.81509486 | N19: 0.55114382 | O19: 0.87599013 | P19: 0.9402011 | Q19: 0.13961207 | R19: 0.50773764 | U19: Ti | V19: {=_xlfn.RANDARRAY(9, 6, 0.1,1,FALSE)} -> 0.87407494 | W19: 0.1616376 | X19: 0.13592546 | Y19: 0.64719996 | Z19: 0.61675058 | AA19: 0.59749903
L20: cat | M20: 0.55434696 | N20: 0.20676972 | O20: 0.28566684 | P20: 0.26753727 | Q20: 0.96215895 | R20: 0.90933916 | U20: amo | V20: 0.10054551 | W20: 0.5714363 | X20: 0.17186502 | Y20: 0.50482714 | Z20: 0.60754361 | AA20: 0.40792812
L21: is | M21: 0.92701969 | N21: 0.64751739 | O21: 0.97386071 | P21: 0.62071448 | Q21: 0.10874277 | R21: 0.47095758 | U21: molto | V21: 0.50391991 | W21: 0.44164665 | X21: 0.21408732 | Y21: 0.50996844 | Z21: 0.52520804 | AA21: 0.57030463
B22: *applied to attention score before softmax* | L22: a | M22: 0.46214985 | N22: 0.89997655 | O22: 0.7277061 | P22: 0.18032843 | Q22: 0.26507507 | R22: 0.94154795 | U22: ke | V22: 0.4550467 | W22: 0.50541554 | X22: 0.45972937 | Y22: 0.35029094 | Z22: 0.23609518 | AA22: 0.12252997
L23: lovely | M23: 0.29483136 | N23: 0.7624218 | O23: 0.98975632 | P23: 0.61433463 | Q23: 0.40733789 | R23: 0.8128624 | U23: qi | V23: 0.24036545 | W23: 0.35154396 | X23: 0.29067864 | Y23: 0.67067555 | Z23: 0.87483164 | AA23: 0.45587319
B24: PADDING MASK for INPUT SEQUENCE | L24: cat | M24: 0.94494223 | N24: 0.56625407 | O24: 0.59216155 | P24: 0.61709469 | Q24: 0.28425962 | R24: 0.68364143 | U24: re | V24: 0.41348251 | W24: 0.9589054 | X24: 0.39051494 | Y24: 0.38853535 | Z24: 0.31035455 | AA24: 0.98070852
L25: Token 7 | M25: 0.52241323 | N25: 0.51939413 | O25: 0.9761818 | P25: 0.68740915 | Q25: 0.57933771 | R25: 0.63919627 | U25: Token 7 | V25: 0.94428595 | W25: 0.9237936 | X25: 0.3794555 | Y25: 0.67736862 | Z25: 0.46293595 | AA25: 0.9294524
D26: {=TRANSPOSE(B6:B11)} -> Your | E26: cat | F26: is | G26: a | H26: lovely | I26: cat | L26: Token 8 | M26: 0.11807417 | N26: 0.78151559 | O26: 0.1392853 | P26: 0.46304748 | Q26: 0.3589966 | R26: 0.51002404 | U26: Token 8 | V26: 0.37457109 | W26: 0.72388355 | X26: 0.72238557 | Y26: 0.92283018 | Z26: 0.3979512 | AA26: 0.37367
C27: Padding? | D27: 0 | E27: 0 | F27: 0 | G27: 0 | H27: 0 | I27: 0 | L27: Token 37k | M27: 0.2464781 | N27: 0.84797223 | O27: 0.12851555 | P27: 0.8711776 | Q27: 0.57898836 | R27: 0.18231091 | U27: Token 37k | V27: 0.32733167 | W27: 0.74714566 | X27: 0.97297695 | Y27: 0.8859741 | Z27: 0.21665774 | AA27: 0.65906009
B29: PADDING MASK for OUTPUT SEQUENCE
D31: {=TRANSPOSE(B14:B19)} -> Ti | E31: amo | F31: molto | G31: <pad> | H31: <pad> | I31: <pad>
C32: Padding? | D32: 0 | E32: 0 | F32: 0 | G32: 1 | H32: 1 | I32: 1

Sheet + Positional Embedding
B2: POSITION IDs to POSITION EMBEDDING
B3: POSITION EMBEDDING (sequence, dmodel)
B6: Position in sequence | D6: 0 | E6: 1 | F6: 2 | O6: 0 | P6: 1 | Q6: 2 | R6: 3 | S6: … | T6: 512
B7: Sentence 1 | D7: YOUR | E7: CAT | F7: IS | G7: … | N7: Your | O7: {=_xlfn.RANDARRAY(6, 6, -1, 1, FALSE)} -> -0.72553715 | P7: -0.38373385 | Q7: -0.11150732 | R7: 0.53718979 | S7: -0.72104629 | T7: -0.62016356
N8: cat | O8: -0.15709553 | P8: 0.17358548 | Q8: 0.99265791 | R8: 0.084143572 | S8: 0.6205748 | T8: -0.91223147
D9: PE(0,0) | E9: PE(1,0) | F9: PE(2,0) | N9: is | O9: -0.68068255 | P9: 0.13165745 | Q9: -0.17325373 | R9: -0.07900618 | S9: 0.68430149 | T9: 0.30965211 | U9: #VALUE!
D10: PE(0,1) | E10: PE(1,1) | F10: PE(2,1) | N10: a | O10: 0.10729962 | P10: 0.43755854 | Q10: -0.38840813 | R10: -0.24206522 | S10: -0.87414737 | T10: -0.36455423
D11: PE(0,2) | E11: PE(1,2) | F11: PE(2,2) | N11: lovely | O11: 0.24228591 | P11: -0.14902619 | Q11: 0.74565224 | R11: 0.50333572 | S11: 0.26440403 | T11: 0.54897907
D12: … | E12: … | F12: … | N12: cat | O12: -0.48623756 | P12: -0.69129731 | Q12: -0.387351 | R12: -0.73830236 | S12: -0.69461506 | T12: -0.24592351
D13: PE(0, 510) | E13: PE(1, 510) | F13: PE(2, 510)
D14: PE(0, 511) | E14: PE(1, 511) | F14: PE(2, 511)
B16: Position in sequence | D16: 0 | E16: 1 | F16: 2
B17: Sentence 2 | D17: I | E17: LOVE | F17: YOU
D19: PE(0,0) | E19: PE(1,0) | F19: PE(2,0)
D20: PE(0,1) | E20: PE(1,1) | F20: PE(2,1)
D21: PE(0,2) | E21: PE(1,2) | F21: PE(2,2)
D22: … | E22: … | F22: …
D23: PE(0, 510) | E23: PE(1, 510) | F23: PE(2, 510)
D24: PE(0, 511) | E24: PE(1, 511) | F24: PE(2, 511) | N24: IMPLEMENTATION

Sheet -> Q, K, V
B2: INPUT EMBEDDING + POSITIONAL EMBEDDING = ENCODER INPUT | V2: ENCODER INPUT to Q, K, V MATRIX
B3: ENCODER INPUT (sequence, dmodel) | V3: Q, K, V MATRIX (sequence, dmodel)
M5: WQ (dmodel, dmodel) | V5: Q' (sequence, dmodel)
D6: 0 | E6: 1 | F6: 2 | G6: 3 | H6: … | I6: 512 | M6: 0 | N6: 1 | O6: 2 | P6: 3 | Q6: … | R6: 512 | V6: 0 | W6: 1 | X6: 2 | Y6: 3 | Z6: … | AA6: 512
B7: E1 | C7: Your | D7: {=_xlfn.ANCHORARRAY('Input | Output Embedding'!D6)+_xlfn.ANCHORARRAY('+ Positional Embedding'!O7)} -> 0.089557704 | E7: 0.16740997 | F7: 0.76448281 | G7: 1.4773909 | H7: -0.58143422 | I7: -0.11242592 | K7: WQ | L7: {=TRANSPOSE(M6:R6)} -> 0 | M7: {=_xlfn.RANDARRAY(6,6,M35,N35,FALSE)} -> -0.010836384 | N7: 0.0038233758 | O7: -0.0077842022 | P7: 0.017556346 | Q7: 0.037530192 | R7: 0.018836053 | T7: Q1 | U7: Your | V7: {=MMULT(_xlfn.ANCHORARRAY(D7),_xlfn.ANCHORARRAY(M7))} -> -0.0029266775 | W7: 0.042132944 | X7: -0.058513667 | Y7: 0.027939427 | Z7: 0.034691587 | AA7: 0.094637688
B8: E2 | C8: cat | D8: 0.39725142 | E8: 0.3803552 | F8: 1.2783247 | G8: 0.35168085 | H8: 1.5827337 | I8: -0.0028923101 | K8: WQ | L8: 1 | M8: 0.040157434 | N8: -0.028272112 | O8: -0.035086894 | P8: 0.0012068701 | Q8: -0.037629458 | R8: -0.016043654 | T8: Q2 | U8: cat | V8: -0.011885274 | W8: 0.03048038 | X8: -0.021717983 | Y8: 0.024174366 | Z8: 0.046752269 | AA8: -0.029612918
B9: E3 | C9: is | D9: 0.24633714 | E9: 0.77917484 | F9: 0.80060698 | G9: 0.5417083 | H9: 0.79304426 | I9: 0.78060969 | J9: x | K9: WQ | L9: 2 | M9: 0.028316962 | N9: 0.041277272 | O9: 0.0012180757 | P9: 0.011671938 | Q9: -0.0021014452 | R9: 0.014333944 | S9: = | T9: Q3 | U9: is | V9: 0.033031642 | W9: -0.014199721 | X9: -0.010358617 | Y9: 0.047795175 | Z9: -0.0015439889 | AA9: -0.037225925
B10: E4 | C10: a | D10: 0.56944947 | E10: 1.3375351 | F10: 0.33929797 | G10: -0.061736786 | H10: -0.60907229 | I10: 0.57699373 | K10: WQ | L10: 3 | M10: -0.030354106 | N10: 0.0044144105 | O10: -0.03150571 | P10: 0.013614049 | Q10: 0.034080697 | R10: 0.038696011 | T10: Q4 | U10: a | V10: 0.094152176 | W10: -0.031921078 | X10: -0.026437352 | Y10: 0.035974141 | Z10: -0.058268547 | AA10: -0.0063355277
B11: E5 | C11: lovely | D11: 0.53711727 | E11: 0.61339561 | F11: 1.7354086 | G11: 1.1176704 | H11: 0.67174192 | I11: 1.3618415 | K11: WQ | L11: … | M11: -0.030513647 | N11: -0.0092762084 | O11: 0.0027573706 | P11: -0.0018109988 | Q11: 0.023247679 | R11: -0.039828128 | T11: Q5 | U11: lovely | V11: 0.052578294 | W11: 0.018071719 | X11: 0.00027714649 | Y11: 0.091959516 | Z11: 0.01802859 | AA11: -0.011070532
B12: E6 | C12: cat | D12: 0.45870466 | E12: -0.12504324 | F12: 0.20481055 | G12: -0.12120767 | H12: -0.41035544 | I12: 0.43771792 | K12: WQ | L12: 512 | M12: 0.028672934 | N12: -0.027151076 | O12: 0.04202194 | P12: 0.034904456 | Q12: -0.021374249 | R12: -0.038710089 | T12: Q6 | U12: cat | V12: 0.024558746 | W12: 0.0051300274 | X12: 0.022147191 | Y12: 0.024664134 | Z12: -0.0015363604 | AA12: 0.0082914154
M14: WK (dmodel, dmodel) | V14: K' (sequence, dmodel)
M15: 0 | N15: 1 | O15: 2 | P15: 3 | Q15: … | R15: 512 | V15: 0 | W15: 1 | X15: 2 | Y15: 3 | Z15: … | AA15: 512
K16: WK | L16: {=TRANSPOSE(M15:R15)} -> 0 | M16: {=_xlfn.RANDARRAY(6,6,M35,N35,FALSE)} -> -0.041821707 | N16: -0.0076589162 | O16: 0.020136484 | P16: 0.042328774 | Q16: -0.042380574 | R16: -0.0332676 | T16: K1 | U16: Your | V16: {=MMULT(_xlfn.ANCHORARRAY(D7),_xlfn.ANCHORARRAY(M16))} -> -0.084287414 | W16: -0.063471521 | X16: -0.014128377 | Y16: 0.019868774 | Z16: 0.048217841 | AA16: 0.023787597
K17: WK | L17: 1 | M17: 0.0070609142 | N17: 0.00079235133 | O17: 0.034958262 | P17: -0.0064762022 | Q17: -0.029642942 | R17: 0.03450988 | T17: K2 | U17: cat | V17: 0.019215474 | W17: 0.0033896625 | X17: -0.020282487 | Y17: 0.052210013 | Z17: -0.019097341 | AA17: 0.092763542
J18: x | K18: WK | L18: 2 | M18: 0.00032462968 | N18: -0.0056375063 | O18: 0.02567396 | P18: -0.0077626826 | Q18: 0.0136666 | R18: 0.026227511 | S18: = | T18: K3 | U18: is | V18: 0.019863727 | W18: -0.028965898 | X18: 0.0038411412 | Y18: 0.0088833902 | Z18: -0.043411643 | AA18: 0.042086608
K19: WK | L19: 3 | M19: -0.041447537 | N19: -0.034973508 | O19: -0.042437747 | P19: 0.023249478 | Q19: 0.024713653 | R19: 0.011307984 | T19: K4 | U19: a | V19: -0.012856145 | W19: -0.025500447 | X19: 0.095296618 | Y19: -0.020599601 | Z19: -0.07293105 | AA19: -0.0090540244
K20: WK | L20: … | M20: 0.029942184 | N20: 0.016157929 | O20: -0.037567325 | P20: 0.024970028 | Q20: -0.01089453 | R20: 0.034897018 | T20: K5 | U20: lovely | V20: -0.0034601183 | W20: -0.071394138 | X20: 0.010896309 | Y20: 0.0084837834 | Z20: -0.041524306 | AA20: 0.030104921
K21: WK | L21: 512 | M21: 0.029606828 | N21: -0.021844066 | O21: 0.0049561998 | P21: -0.029053675 | Q21: -0.032748786 | R21: -0.040232672 | T21: K6 | U21: cat | V21: -0.014303984 | W21: -0.016719855 | X21: 0.032852857 | Y21: -0.0071455841 | Z21: -0.025794039 | AA21: -0.047504916
M24: WV (dmodel, dmodel) | V24: V' (sequence, dmodel)
M25: 0 | N25: 1 | O25: 2 | P25: 3 | Q25: … | R25: 512 | V25: 0 | W25: 1 | X25: 2 | Y25: 3 | Z25: … | AA25: 512
K26: WV | L26: {=TRANSPOSE(M25:R25)} -> 0 | M26: {=_xlfn.RANDARRAY(6,6,M35,N35,FALSE)} -> 0.036511734 | N26: 0.019879844 | O26: 0.030970359 | P26: 0.015771734 | Q26: 0.023930813 | R26: 0.033875414 | T26: V1 | U26: Your | V26: {=MMULT(_xlfn.ANCHORARRAY(D7),_xlfn.ANCHORARRAY(M26))} -> 0.062137708 | W26: -0.0047661096 | X26: -0.012906227 | Y26: -0.068176364 | Z26: -0.11545215 | AA26: -0.023008493
K27: WV | L27: 1 | M27: -0.002575828 | N27: 0.012536387 | O27: 0.0077215393 | P27: -0.043123756 | Q27: -0.025196193 | R27: 0.03763087 | T27: V2 | U27: cat | V27: 0.0078916577 | W27: -0.021897807 | X27: -0.025668942 | Y27: -0.064055286 | Z27: -0.0051285925 | AA27: -0.056921823
J28: x | K28: WV | L28: 2 | M28: -0.0042658357 | N28: -0.0033139815 | O28: -0.014629228 | P28: -0.03673024 | Q28: -0.040763777 | R28: -0.033596374 | S28: = | T28: V3 | U28: is | V28: 0.0048616726 | W28: -0.025214403 | X28: -0.0026149946 | Y28: -0.076426798 | Z28: -0.0077071847 | AA28: -0.042095853
K29: WV | L29: 3 | M29: 0.037776253 | N29: -0.012321884 | O29: -0.0078284804 | P29: -0.023410896 | Q29: -0.037802267 | R29: -0.016045641 | T29: V4 | U29: a | V29: 0.0095974612 | W29: 0.024821301 | X29: 0.037921842 | Y29: -0.064075313 | Z29: -0.033511941 | AA29: 0.053900726
K30: WV | L30: … | M30: -0.0085364782 | N30: -0.016464228 | O30: -0.012269874 | P30: 0.00078889277 | Q30: 0.038199055 | R30: -0.02287082 | T30: V5 | U30: lovely | V30: 0.025475083 | W30: -0.04273601 | X30: -0.0045692305 | Y30: -0.11651444 | Z30: -0.039602567 | AA30: -0.095742285
K31: WV | L31: 512 | M31: -0.015890336 | N31: -0.022411532 | O31: 0.012071327 | P31: -0.0067233085 | Q31: 0.036958331 | R31: -0.033351535 | T31: V6 | U31: cat | V31: 0.008165238 | W31: 0.0053124114 | X31: 0.021512219 | Y31: 0.0046751024 | Z31: 0.010862995 | AA31: 0.00068388825
M34: lower | N34: upper
M35: =-1/SQRT(512) -> -0.044194174 | N35: =1/SQRT(512) -> 0.044194174

Sheet -> Self - Attention
B2: Self - Attention (Single Head)
B3: Q, K, V MATRIX (sequence, dmodel)
Y4: Q, K MATRIX to ATTENTION SCORE MATRIX
Y5: ATTENTION SCORE MATRIX | AR5: ATTENTION SCORE MATRIX to ATTENTION OUTPUT MATRIX
E6: "meaning and positional meaning" | Y6: A's (sequence, sequence) | AR6: ATTENTION OUTPUT MATRIX
E7: Q' (sequence, dmodel) | O7: K'T (sequence, dmodel) | V7: MASKED? | W7: Yes | AI7: V' (sequence, dmodel) | AR7: A' (sequence, dmodel)
F8: 0 | G8: 1 | H8: 2 | I8: 3 | J8: … | K8: 512 | O8: Your | P8: cat | Q8: is | R8: a | S8: lovely | T8: cat | Y8: Your | Z8: cat | AA8: is | AB8: a | AC8: lovely | AD8: cat | AI8: 0 | AJ8: 1 | AK8: 2 | AL8: 3 | AM8: … | AN8: 512 | AR8: 0 | AS8: 1 | AT8: 2 | AU8: 3 | AV8: … | AW8: 512
D9: Q1 | E9: Your | F9: {=_xlfn.ANCHORARRAY('-> Q, K, V'!V7)} -> -0.0029266775 | G9: 0.042132944 | H9: -0.058513667 | I9: 0.027939427 | J9: 0.034691587 | K9: 0.094637688 | N9: 0 | O9: {=TRANSPOSE(_xlfn.ANCHORARRAY('-> Q, K, V'!V16))} -> -0.084287414 | P9: 0.019215474 | Q9: 0.019863727 | R9: -0.012856145 | S9: -0.0034601183 | T9: -0.014303984 | W9: Q1 x K1 | X9: {=TRANSPOSE(Y8:AD8)} -> Your | Y9: {=_xlfn.LET( _xlpm.base_matrix, MMULT(_xlfn.ANCHORARRAY(F9),_xlfn.ANCHORARRAY( O9))/SQRT(512), IF(W7="Yes", _xlfn.MAKEARRAY(6, 6, _xlfn.LAMBDA(_xlpm.r,_xlpm.c, IF(_xlpm.r >= _xlpm.c, INDEX(_xlpm.base_matrix, _xlpm.r, _xlpm.c), -10000000000))), _xlpm.base_matrix ) )} -> 0.00012720065 | Z9: -10000000000 | AA9: -10000000000 | AB9: -10000000000 | AC9: -10000000000 | AD9: -10000000000 | AG9: V1 | AH9: Your | AI9: {=_xlfn.ANCHORARRAY('-> Q, K, V'!V26)} -> 0.062137708 | AJ9: -0.0047661096 | AK9: -0.012906227 | AL9: -0.068176364 | AM9: -0.11545215 | AN9: -0.023008493 | AP9: A1 (Q1, K1, V1) | AQ9: Your | AR9: {=MMULT(Y36:AD41,_xlfn.ANCHORARRAY(AI9))} -> 0.062137708 | AS9: -0.0047661096 | AT9: -0.012906227 | AU9: -0.068176364 | AV9: -0.11545215 | AW9: -0.023008493
D10: Q2 | E10: cat | F10: -0.011885274 | G10: 0.03048038 | H10: -0.021717983 | I10: 0.024174366 | J10: 0.046752269 | K10: -0.029612918 | N10: 1 | O10: -0.063471521 | P10: 0.0033896625 | Q10: -0.028965898 | R10: -0.025500447 | S10: -0.071394138 | T10: -0.016719855 | W10: Q2 X K2 | X10: cat | Y10: 6.2056182e-05 | Z10: -9.1140204e-05 | AA10: -10000000000 | AB10: -10000000000 | AC10: -10000000000 | AD10: -10000000000 | AG10: V2 | AH10: cat | AI10: 0.0078916577 | AJ10: -0.021897807 | AK10: -0.025668942 | AL10: -0.064055286 | AM10: -0.0051285925 | AN10: -0.056921823 | AP10: … | AQ10: cat | AR10: 0.035016761 | AS10: -0.013331302 | AT10: -0.019287096 | AU10: -0.066115983 | AV10: -0.060294597 | AW10: -0.039963859
B11: softmax | D11: Q3 | E11: is | F11: 0.033031642 | G11: -0.014199721 | H11: -0.010358617 | I11: 0.047795175 | J11: -0.0015439889 | K11: -0.037225925 | L11: x | N11: 2 | O11: -0.014128377 | P11: -0.020282487 | Q11: 0.0038411412 | R11: 0.095296618 | S11: 0.010896309 | T11: 0.032852857 | V11: = | W11: Q3 X K3 | X11: is | Y11: -7.7200813e-05 | Z11: -5.818203e-06 | AA11: -2.0971167e-06 | AB11: -10000000000 | AC11: -10000000000 | AD11: -10000000000 | AF11: x | AG11: V3 | AH11: is | AI11: 0.0048616726 | AJ11: -0.025214403 | AK11: -0.0026149946 | AL11: -0.076426798 | AM11: -0.0077071847 | AN11: -0.042095853 | AO11: = | AP11: … | AQ11: is | AR11: 0.02496277 | AS11: -0.017293081 | AT11: -0.01373006 | AU11: -0.069552857 | AV11: -0.042760869 | AW11: -0.040675812
D12: Q4 | E12: a | F12: 0.094152176 | G12: -0.031921078 | H12: -0.026437352 | I12: 0.035974141 | J12: -0.058268547 | K12: -0.0063355277 | N12: 3 | O12: 0.019868774 | P12: 0.052210013 | Q12: 0.0088833902 | R12: -0.020599601 | S12: 0.0084837834 | T12: -0.0071455841 | W12: Q4 X K4 | X12: a | Y12: -0.00034390914 | Z12: 0.00020508178 | AA12: 0.00023315746 | AB12: 2.8729432e-05 | AC12: -10000000000 | AD12: -10000000000 | AG12: V4 | AH12: a | AI12: 0.0095974612 | AJ12: 0.024821301 | AK12: 0.037921842 | AL12: -0.064075313 | AM12: -0.033511941 | AN12: 0.053900726 | AP12: … | AQ12: a | AR12: 0.02111689 | AS12: -0.0067660509 | AT12: -0.0008171421 | AU12: -0.06818368 | AV12: -0.04043975 | AW12: -0.017033844
D13: Q5 | E13: lovely | F13: 0.052578294 | G13: 0.018071719 | H13: 0.00027714649 | I13: 0.091959516 | J13: 0.01802859 | K13: -0.011070532 | N13: … | O13: 0.048217841 | P13: -0.019097341 | Q13: -0.043411643 | R13: -0.07293105 | S13: -0.041524306 | T13: -0.025794039 | W13: Q5 X K5 | X13: lovely | Y13: -0.00013919231 | Z13: 0.00019869348 | AA13: 3.992602e-06 | AB13: -0.00018646938 | AC13: -7.8261678e-05 | AD13: -10000000000 | AG13: V5 | AH13: lovely | AI13: 0.025475083 | AJ13: -0.04273601 | AK13: -0.0045692305 | AL13: -0.11651444 | AM13: -0.039602567 | AN13: -0.095742285 | AP13: … | AQ13: lovely | AR13: 0.021991433 | AS13: -0.013960182 | AT13: -0.0015695792 | AU13: -0.077849268 | AV13: -0.040277234 | AW13: -0.032777032
D14: Q6 | E14: cat | F14: 0.024558746 | G14: 0.0051300274 | H14: 0.022147191 | I14: 0.024664134 | J14: -0.0015363604 | K14: 0.0082914154 | N14: 512 | O14: 0.023787597 | P14: 0.092763542 | Q14: 0.042086608 | R14: -0.0090540244 | S14: 0.030104921 | T14: -0.047504916 | W14: Q6 X K6 | X14: cat | Y14: -9.2600437e-05 | Z14: 9.3969767e-05 | AA14: 4.680417e-05 | AB14: 5.2719673e-05 | AC14: 1.3821571e-05 | AD14: -1.0604676e-05 | AG14: V6 | AH14: cat | AI14: 0.008165238 | AJ14: 0.0053124114 | AK14: 0.021512219 | AL14: 0.0046751024 | AM14: 0.010862995 | AN14: 0.00068388825 | AP14: An(Qn, Kn, Vn) | AQ14: cat | AR14: 0.019687126 | AS14: -0.010746939 | AT14: 0.0022791329 | AU14: -0.064095791 | AV14: -0.031754786 | AW14: -0.027197448
O16: K1 | P16: K2 | Q16: K3 | R16: K4 | S16: K5 | T16: K6
K17: sqrt(dk) | AI17: 0 | AJ17: 1 | AK17: 2 | AL17: 3 | AM17: … | AN17: 512
AH18: Your | AI18: =$Y$36*AI9 -> 0.062137708 | AJ18: =$Y$36*AJ9 -> -0.0047661096 | AK18: =$Y$36*AK9 -> -0.012906227 | AL18: =$Y$36*AL9 -> -0.068176364 | AM18: =$Y$36*AM9 -> -0.11545215 | AN18: =$Y$36*AN9 -> -0.023008493
AH19: cat | AI19: =$Z$36*AI10 -> 0 | AJ19: =$Z$36*AJ10 -> 0 | AK19: =$Z$36*AK10 -> 0 | AL19: =$Z$36*AL10 -> 0 | AM19: =$Z$36*AM10 -> 0 | AN19: =$Z$36*AN10 -> 0
AH20: is | AI20: =$AA$36*AI11 -> 0 | AJ20: =$AA$36*AJ11 -> 0 | AK20: =$AA$36*AK11 -> 0 | AL20: =$AA$36*AL11 -> 0 | AM20: =$AA$36*AM11 -> 0 | AN20: =$AA$36*AN11 -> 0
AH21: a | AI21: =$AB$36*AI12 -> 0 | AJ21: =$AB$36*AJ12 -> 0 | AK21: =$AB$36*AK12 -> 0 | AL21: =$AB$36*AL12 -> 0 | AM21: =$AB$36*AM12 -> 0 | AN21: =$AB$36*AN12 -> 0
AH22: lovely | AI22: =$AC$36*AI13 -> 0 | AJ22: =$AC$36*AJ13 -> 0 | AK22: =$AC$36*AK13 -> 0 | AL22: =$AC$36*AL13 -> 0 | AM22: =$AC$36*AM13 -> 0 | AN22: =$AC$36*AN13 -> 0
AH23: cat | AI23: =$AD$36*AI14 -> 0 | AJ23: =$AD$36*AJ14 -> 0 | AK23: =$AD$36*AK14 -> 0 | AL23: =$AD$36*AL14 -> 0 | AM23: =$AD$36*AM14 -> 0 | AN23: =$AD$36*AN14 -> 0
AI25: 0 | AJ25: 1 | AK25: 2 | AL25: 3 | AM25: … | AN25: 512
Z26: apply softmax to get ATTENTION WEIGHTS | AH26: Your | AI26: =SUM(AI18:AI23) -> 0.062137708 | AJ26: =SUM(AJ18:AJ23) -> -0.0047661096 | AK26: =SUM(AK18:AK23) -> -0.012906227 | AL26: =SUM(AL18:AL23) -> -0.068176364 | AM26: =SUM(AM18:AM23) -> -0.11545215 | AN26: =SUM(AN18:AN23) -> -0.023008493
W27: Sum exp(x) | Y27: Your | Z27: cat | AA27: is | AB27: a | AC27: lovely | AD27: cat | AH27: cat
W28: =SUM(Y28:AD28) -> 1.0001272 | X28: {=TRANSPOSE(Y27:AD27)} -> Your | Y28: {=EXP(_xlfn.ANCHORARRAY(Y9))} -> 1.0001272 | Z28: 0 | AA28: 0 | AB28: 0 | AC28: 0 | AD28: 0 | AH28: is
W29: =SUM(Y29:AD29) -> 1.9999709 | X29: cat | Y29: 1.0000621 | Z29: 0.99990886 | AA29: 0 | AB29: 0 | AC29: 0 | AD29: 0 | AH29: a
W30: =SUM(Y30:AD30) -> 2.9999149 | X30: is | Y30: 0.9999228 | Z30: 0.99999418 | AA30: 0.9999979 | AB30: 0 | AC30: 0 | AD30: 0 | AH30: lovely
W31: =SUM(Y31:AD31) -> 4.0001232 | X31: a | Y31: 0.99965615 | Z31: 1.0002051 | AA31: 1.0002332 | AB31: 1.0000287 | AC31: 0 | AD31: 0 | AH31: cat
W32: =SUM(Y32:AD32) -> 4.9997988 | X32: lovely | Y32: 0.99986082 | Z32: 1.0001987 | AA32: 1.000004 | AB32: 0.99981355 | AC32: 0.99992174 | AD32: 0
W33: =SUM(Y33:AD33) -> 6.0001041 | X33: cat | Y33: 0.9999074 | Z33: 1.000094 | AA33: 1.0000468 | AB33: 1.0000527 | AC33: 1.0000138 | AD33: 0.9999894
W35: Sum | Y35: Your | Z35: cat | AA35: is | AB35: a | AC35: lovely | AD35: cat
W36: =SUM(Y36:AD36) -> 1 | X36: {=TRANSPOSE(Y35:AD35)} -> Your | Y36: =Y28/$W$28 -> 1 | Z36: =Z28/$W$28 -> 0 | AA36: =AA28/$W$28 -> 0 | AB36: =AB28/$W$28 -> 0 | AC36: =AC28/$W$28 -> 0 | AD36: =AD28/$W$28 -> 0
W37: =SUM(Y37:AD37) -> 1 | X37: cat | Y37: =Y29/$W$29 -> 0.5000383 | Z37: =Z29/$W$29 -> 0.4999617 | AA37: =AA29/$W$29 -> 0 | AB37: =AB29/$W$29 -> 0 | AC37: =AC29/$W$29 -> 0 | AD37: =AD29/$W$29 -> 0
W38: =SUM(Y38:AD38) -> 1 | X38: is | Y38: =Y30/$W$30 -> 0.33331706 | Z38: =Z30/$W$30 -> 0.33334085 | AA38: =AA30/$W$30 -> 0.33334209 | AB38: =AB30/$W$30 -> 0 | AC38: =AC30/$W$30 -> 0 | AD38: =AD30/$W$30 -> 0
W39: =SUM(Y39:AD39) -> 1 | X39: a | Y39: =Y31/$W$31 -> 0.24990634 | Z39: =Z31/$W$31 -> 0.25004358 | AA39: =AA31/$W$31 -> 0.2500506 | AB39: =AB31/$W$31 -> 0.24999948 | AC39: =AC31/$W$31 -> 0 | AD39: =AD31/$W$31 -> 0
W40: =SUM(Y40:AD40) -> 1 | X40: lovely | Y40: =Y32/$W$32 -> 0.19998021 | Z40: =Z32/$W$32 -> 0.20004779 | AA40: =AA32/$W$32 -> 0.20000885 | AB40: =AB32/$W$32 -> 0.19997076 | AC40: =AC32/$W$32 -> 0.1999924 | AD40: =AD32/$W$32 -> 0
W41: =SUM(Y41:AD41) -> 1 | X41: cat | Y41: =Y33/$W$33 -> 0.16664834 | Z41: =Z33/$W$33 -> 0.16667944 | AA41: =AA33/$W$33 -> 0.16667158 | AB41: =AB33/$W$33 -> 0.16667256 | AC41: =AC33/$W$33 -> 0.16666608 | AD41: =AD33/$W$33 -> 0.16666201

Sheet -> Add & Norm
C2: Normalization
E4: ATTENTION OUTPUT MATRIX | X4: ATTENTION OUTPUT MATRIX
E5: A' (sequence, dmodel) | X5: A' (sequence, dmodel)
E6: 0 | F6: 1 | G6: 2 | H6: 3 | I6: … | J6: 512 | X6: 0 | Y6: 1 | Z6: 2 | AA6: 3 | AB6: … | AC6: 512 | AE6: Mean | AF6: Std. Dev
C7: A1 (Q1, K1, V1) | D7: Your | E7: {='-> Self - Attention'!AR9:AW14} -> 0.062137708 | F7: -0.0047661096 | G7: -0.012906227 | H7: -0.068176364 | I7: -0.11545215 | J7: -0.023008493 | V7: A1 (Q1, K1, V1) | W7: Your | X7: =(E7-$AE$7)/$AF$7 -> 1.4789857 | Y7: =(F7-$AE$7)/$AF$7 -> 0.36926404 | Z7: =(G7-$AE$7)/$AF$7 -> 0.23424536 | AA7: =(H7-$AE$7)/$AF$7 -> -0.68251048 | AB7: =(I7-$AE$7)/$AF$7 -> -1.4666655 | AC7: =(J7-$AE$7)/$AF$7 -> 0.066680891 | AE7: =AVERAGE(E7:J7) -> -0.027028606 | AF7: =STDEV(E7:J7) -> 0.060288829
C8: … | D8: cat | E8: 0.035016761 | F8: -0.013331302 | G8: -0.019287096 | H8: -0.066115983 | I8: -0.060294597 | J8: -0.039963859 | V8: … | W8: cat | X8: =(E8-$AE$8)/$AF$8 -> 1.6784952 | Y8: =(F8-$AE$8)/$AF$8 -> 0.37685832 | Z8: =(G8-$AE$8)/$AF$8 -> 0.21651517 | AA8: =(H8-$AE$8)/$AF$8 -> -1.0442221 | AB8: =(I8-$AE$8)/$AF$8 -> -0.8874975 | AC8: =(J8-$AE$8)/$AF$8 -> -0.34014906 | AE8: =AVERAGE(E8:J8) -> -0.027329346 | AF8: =STDEV(E8:J8) -> 0.037144049
C9: … | D9: is | E9: 0.02496277 | F9: -0.017293081 | G9: -0.01373006 | H9: -0.069552857 | I9: -0.042760869 | J9: -0.040675812 | V9: … | W9: is | X9: =(E9-$AE$9)/$AF$9 -> 1.5937272 | Y9: =(F9-$AE$9)/$AF$9 -> 0.28533639 | Z9: =(G9-$AE$9)/$AF$9 -> 0.39566013 | AA9: =(H9-$AE$9)/$AF$9 -> -1.3328114 | AB9: =(I9-$AE$9)/$AF$9 -> -0.50323655 | AC9: =(J9-$AE$9)/$AF$9 -> -0.4386758 | AE9: =AVERAGE(E9:J9) -> -0.026508318 | AF9: =STDEV(E9:J9) -> 0.032296046
C10: … | D10: a | E10: 0.02111689 | F10: -0.0067660509 | G10: -0.0008171421 | H10: -0.06818368 | I10: -0.04043975 | J10: -0.017033844 | V10: … | W10: a | X10: =(E10-$AE$10)/$AF$10 -> 1.2623045 | Y10: =(F10-$AE$10)/$AF$10 -> 0.37805601 | Z10: =(G10-$AE$10)/$AF$10 -> 0.56671306 | AA10: =(H10-$AE$10)/$AF$10 -> -1.5696741 | AB10: =(I10-$AE$10)/$AF$10 -> -0.6898341 | AC10: =(J10-$AE$10)/$AF$10 -> 0.052434673 | AE10: =AVERAGE(E10:J10) -> -0.018687263 | AF10: =STDEV(E10:J10) -> 0.031532925
C11: … | D11: lovely | E11: 0.021991433 | F11: -0.013960182 | G11: -0.0015695792 | H11: -0.077849268 | I11: -0.040277234 | J11: -0.032777032 | V11: … | W11: lovely | X11: =(E11-$AE$11)/$AF$11 -> 1.3341463 | Y11: =(F11-$AE$11)/$AF$11 -> 0.29290818 | Z11: =(G11-$AE$11)/$AF$11 -> 0.65176738 | AA11: =(H11-$AE$11)/$AF$11 -> -1.5574608 | AB11: =(I11-$AE$11)/$AF$11 -> -0.46929175 | AC11: =(J11-$AE$11)/$AF$11 -> -0.25206932 | AE11: =AVERAGE(E11:J11) -> -0.024073644 | AF11: =STDEV(E11:J11) -> 0.034527755
C12: An(Qn, Kn, Vn) | D12: cat | E12: 0.019687126 | F12: -0.010746939 | G12: 0.0022791329 | H12: -0.064095791 | I12: -0.031754786 | J12: -0.027197448 | V12: An(Qn, Kn, Vn) | W12: cat | X12: =(E12-$AE$12)/$AF$12 -> 1.3098785 | Y12: =(F12-$AE$12)/$AF$12 -> 0.26970435 | Z12: =(G12-$AE$12)/$AF$12 -> 0.71490887 | AA12: =(H12-$AE$12)/$AF$12 -> -1.5536504 | AB12: =(I12-$AE$12)/$AF$12 -> -0.44830093 | AC12: =(J12-$AE$12)/$AF$12 -> -0.29254043 | AE12: =AVERAGE(E12:J12) -> -0.018638117 | AF12: =STDEV(E12:J12) -> 0.029258625
H15: or | K15: each | S15: = | T15: norm | X15: FEED FORWARD MATRIX
X16: E' (sequence, dmodel)
E17: FEED FORWARD MATRIX | X17: 0 | Y17: 1 | Z17: 2 | AA17: 3 | AB17: … | AC17: 512 | AE17: Mean | AF17: Std. Dev
E18: E' (sequence, dmodel) | V18: E1 | W18: Your | X18: =(E20-$AE$18)/$AF$18 -> -0.081770631 | Y18: =(F20-$AE$18)/$AF$18 -> -0.84565408 | Z18: =(G20-$AE$18)/$AF$18 -> 0.32148247 | AA18: =(H20-$AE$18)/$AF$18 -> 0.84208215 | AB18: =(I20-$AE$18)/$AF$18 -> -1.4291475 | AC18: =(J20-$AE$18)/$AF$18 -> 1.1930075 | AE18: =AVERAGE(E20:J20) -> 0.65867494 | AF18: =STDEV(E20:J20) -> 0.18801916
E19: 0 | F19: 1 | G19: 2 | H19: 3 | I19: … | J19: 512 | V19: … | W19: cat | X19: =(E21-$AE$19)/$AF$19 -> -1.4868997 | Y19: =(F21-$AE$19)/$AF$19 -> 1.1959088 | Z19: =(G21-$AE$19)/$AF$19 -> -0.28787208 | AA19: =(H21-$AE$19)/$AF$19 -> 1.0739721 | AB19: =(I21-$AE$19)/$AF$19 -> -0.25382596 | AC19: =(J21-$AE$19)/$AF$19 -> -0.24128309 | AE19: =AVERAGE(E21:J21) -> 0.54941952 | AF19: =STDEV(E21:J21) -> 0.22870324
C20: E1 | D20: Your | E20: {='-> Feed Forward'!Z14:AE19} -> 0.64330049 | F20: 0.49967577 | G20: 0.7191198 | H20: 0.81700252 | I20: 0.38996784 | J20: 0.88298321 | V20: … | W20: is | X20: =(E22-$AE$20)/$AF$20 -> 0.75749835 | Y20: =(F22-$AE$20)/$AF$20 -> -1.4690083 | Z20: =(G22-$AE$20)/$AF$20 -> -0.25307314 | AA20: =(H22-$AE$20)/$AF$20 -> -0.78556137 | AB20: =(I22-$AE$20)/$AF$20 -> 0.70840601 | AC20: =(J22-$AE$20)/$AF$20 -> 1.0417385 | AE20: =AVERAGE(E22:J22) -> 0.59158487 | AF20: =STDEV(E22:J22) -> 0.30164829
C21: … | D21: cat | E21: 0.20936074 | F21: 0.82292772 | G21: 0.48358224 | H21: 0.7950404 | I21: 0.4913687 | J21: 0.49423729 | V21: … | W21: a | X21: =(E23-$AE$21)/$AF$21 -> -0.74200535 | Y21: =(F23-$AE$21)/$AF$21 -> -0.039197986 | Z21: =(G23-$AE$21)/$AF$21 -> 1.0763451 | AA21: =(H23-$AE$21)/$AF$21 -> 0.75173877 | AB21: =(I23-$AE$21)/$AF$21 -> 0.51969975 | AC21: =(J23-$AE$21)/$AF$21 -> -1.5665803 | AE21: =AVERAGE(E23:J23) -> 0.51908989 | AF21: =STDEV(E23:J23) -> 0.28482307
C22: … | D22: is | E22: 0.82008295 | F22: 0.14846101 | G22: 0.51524579 | H22: 0.35462162 | I22: 0.80527433 | J22: 0.9058235 | V22: … | W22: lovely | X22: =(E24-$AE$22)/$AF$22 -> -0.89003666 | Y22: =(F24-$AE$22)/$AF$22 -> 1.237911 | Z22: =(G24-$AE$22)/$AF$22 -> -0.10188096 | AA22: =(H24-$AE$22)/$AF$22 -> -0.7614894 | AB22: =(I24-$AE$22)/$AF$22 -> -0.73025431 | AC22: =(J24-$AE$22)/$AF$22 -> 1.2457504 | AE22: =AVERAGE(E24:J24) -> 0.42659345 | AF22: =STDEV(E24:J24) -> 0.39849874
C23: … | D23: a | E23: 0.30774965 | F23: 0.5079254 | G23: 0.8256578 | H23: 0.73320243 | I23: 0.66711237 | J23: 0.072891681 | V23: En | W23: cat | X23: =(E25-$AE$23)/$AF$23 -> -0.3149538 | Y23: =(F25-$AE$23)/$AF$23 -> 1.1183199 | Z23: =(G25-$AE$23)/$AF$23 -> -1.6968155 | AA23: =(H25-$AE$23)/$AF$23 -> 0.87657767 | AB23: =(I25-$AE$23)/$AF$23 -> -0.026570968 | AC23: =(J25-$AE$23)/$AF$23 -> 0.043442686 | AE23: =AVERAGE(E25:J25) -> 0.64227882 | AF23: =STDEV(E25:J25) -> 0.21020712
C24: … | D24: lovely | E24: 0.071914964 | F24: 0.91989941 | G24: 0.38599402 | H24: 0.12314088 | I24: 0.13558803 | J24: 0.9230234
C25: En | D25: cat | E25: 0.57607329 | F25: 0.87735764 | G25: 0.28559611 | H25: 0.82654169 | I25: 0.63669341 | J25: 0.65141078
E28: CROSS ATTENTION MATRIX
E29: Cn (output_sequence, dmodel)
E30: 0 | F30: 1 | G30: 2 | H30: 3 | I30: … | J30: 512
C31: C1 | D31: y - hat | E31: {=_xlfn.ANCHORARRAY('-> Cross Attention'!W17)} -> 1.5173754 | F31: 0.66131337 | G31: 0.85504526 | H31: 1.4642025 | I31: 1.0067184 | J31: 1.4804822

Sheet -> Linear

Sheet -> Softmax

Sheet -> Feed Forward
B2: Each embedding in the Attention Output Matrix - A1 (Q1, K1, V1) to An (Qn, Kn, Vn)
B3: FEED FORWARD MATRIX (sequence, dmodel)
C6: Feed Forward for A1 (Q1, K1, V1) | J6: Hidden Layers
F7: Input Layer | J7: Layer 1 | N7: Layer n | R7: Output Layer
F9: 1 | G9: {=TRANSPOSE('-> Add & Norm'!X7:AC7)} -> 1.4789857 | J9: 1 | K9: {=_xlfn.RANDARRAY(6,1,0, 1,FALSE)} -> 0.62679711 | N9: 1 | O9: {=_xlfn.RANDARRAY(6,1,0, 1,FALSE)} -> 0.80173759 | R9: 1 | S9: {=_xlfn.RANDARRAY(6,1,0, 1,FALSE)} -> 0.17592527
F10: 2 | G10: 0.36926404 | J10: 2 | K10: 0.092436809 | N10: 2 | O10: 0.88078086 | R10: 2 | S10: 0.38611501
C11: Attention Output 1 | F11: 3 | G11: 0.23424536 | J11: 3 | K11: 0.78714804 | N11: 3 | O11: 0.077519316 | R11: 3 | S11: 0.72378617
C12: 512 (dmodel) | F12: 4 | G12: -0.68251048 | J12: 4 | K12: 0.45795738 | N12: 4 | O12: 0.14231881 | R12: 4 | S12: 0.35011148
F13: … | G13: -1.4666655 | J13: … | K13: 0.20415744 | N13: … | O13: 0.13779554 | R13: … | S13: 0.30426217 | Z13: 1 | AA13: 2 | AB13: 3 | AC13: 4 | AD13: … | AE13: 512
F14: 512 | G14: 0.066680891 | J14: 2048 | K14: 0.6436972 | N14: 2048 | O14: 0.96749055 | R14: 512 | S14: 0.22039559 | X14: E1 | Y14: Your | Z14: {=_xlfn.RANDARRAY(6,6,0, 1,FALSE)} -> 0.64330049 | AA14: 0.49967577 | AB14: 0.7191198 | AC14: 0.81700252 | AD14: 0.38996784 | AE14: 0.88298321
X15: … | Y15: cat | Z15: 0.20936074 | AA15: 0.82292772 | AB15: 0.48358224 | AC15: 0.7950404 | AD15: 0.4913687 | AE15: 0.49423729
X16: … | Y16: is | Z16: 0.82008295 | AA16: 0.14846101 | AB16: 0.51524579 | AC16: 0.35462162 | AD16: 0.80527433 | AE16: 0.9058235
V17: = | X17: … | Y17: a | Z17: 0.30774965 | AA17: 0.5079254 | AB17: 0.8256578 | AC17: 0.73320243 | AD17: 0.66711237 | AE17: 0.072891681
X18: … | Y18: lovely | Z18: 0.071914964 | AA18: 0.91989941 | AB18: 0.38599402 | AC18: 0.12314088 | AD18: 0.13558803 | AE18: 0.9230234
C19: Feed Forward for An (Qn, Kn, Vn) | J19: Hidden Layers | X19: En | Y19: cat | Z19: 0.57607329 | AA19: 0.87735764 | AB19: 0.28559611 | AC19: 0.82654169 | AD19: 0.63669341 | AE19: 0.65141078
F20: Input Layer | J20: Layer 1 | N20: Layer n | R20: Output Layer
F22: 1 | G22: {=TRANSPOSE('-> Add & Norm'!X12:AC12)} -> 1.3098785 | J22: 1 | K22: {=_xlfn.RANDARRAY(6,1,0, 1,FALSE)} -> 0.45964433 | N22: 1 | O22: {=_xlfn.RANDARRAY(6,1,0, 1,FALSE)} -> 0.44766916 | R22: 1 | S22: {=_xlfn.RANDARRAY(6,1,0, 1,FALSE)} -> 0.50472243
F23: 2 | G23: 0.26970435 | J23: 2 | K23: 0.53244398 | N23: 2 | O23: 0.73503697 | R23: 2 | S23: 0.5502747
C24: Attention Output n | F24: 3 | G24: 0.71490887 | J24: 3 | K24: 0.43612091 | N24: 3 | O24: 0.40067517 | R24: 3 | S24: 0.93813485
C25: 512 (dmodel) | F25: 4 | G25: -1.5536504 | J25: 4 | K25: 0.12460032 | N25: 4 | O25: 0.21775543 | R25: 4 | S25: 0.563092
F26: … | G26: -0.44830093 | J26: … | K26: 0.86494996 | N26: … | O26: 0.11288736 | R26: … | S26: 0.50444407
F27: 512 | G27: -0.29254043 | J27: 2048 | K27: 0.60668467 | N27: 2048 | O27: 0.39164908 | R27: 512 | S27: 0.56035628
C46: Embedding | J46: Neurons
C47: {=F9:G14} -> 1 | D47: 1.4789857 | E47: w1 | F47: ="b"&ROW()-46 -> b1 | H47: = | I47: act(z) | J47: {=J9:K14} -> 1 | K47: 0.62679711
C48: 2 | D48: 0.36926404 | E48: w2 | F48: ="b"&ROW()-46 -> b2 | H48: = | I48: act(z) | J48: 2 | K48: 0.092436809
C49: 3 | D49: 0.23424536 | E49: w3 | F49: ="b"&ROW()-46 -> b3 | H49: = | I49: act(z) | J49: 3 | K49: 0.78714804
C50: 4 | D50: -0.68251048 | E50: w4 | F50: ="b"&ROW()-46 -> b4 | H50: = | I50: act(z) | J50: 4 | K50: 0.45795738
C51: … | D51: -1.4666655 | E51: w5 | F51: ="b"&ROW()-46 -> b5 | H51: = | I51: act(z) | J51: … | K51: 0.20415744
C52: 512 | D52: 0.066680891 | E52: w512 | F52: b2048 | H52: = | I52: act(z) | J52: 2048 | K52: 0.6436972
C55: How backpropagation works?

Sheet -> Cross Attention
B3: CROSS ATTENTION
U12: at time step 1
C14: FEED FORWARD MATRIX (from the encoder) | L14: ATTENTION OUTPUT EMBEDDING (from the decoder) | U14: CROSS ATTENTION MATRIX
C15: E' (input_sequence, dmodel) | L15: An (1, dmodel) | U15: Cn (output_sequence, dmodel)
E16: 0 | F16: 1 | G16: 2 | H16: 3 | I16: … | J16: 512 | N16: 0 | O16: 1 | P16: 2 | Q16: 3 | R16: … | S16: 512 | W16: 0 | X16: 1 | Y16: 2 | Z16: 3 | AA16: … | AB16: 512
C17: E1 | D17: Your | E17: {=_xlfn.ANCHORARRAY('-> Add & Norm'!E20)} -> 0.64330049 | F17: 0.49967577 | G17: 0.7191198 | H17: 0.81700252 | I17: 0.38996784 | J17: 0.88298321 | L17: A1 (Q1, K1, V1) | M17: <SOS> | N17: {='Input | Output Embedding'!D14:I14} -> 0.87407494 | O17: 0.1616376 | P17: 0.13592546 | Q17: 0.64719996 | R17: 0.61675058 | S17: 0.59749903 | U17: C1 | V17: y - hat | W17: {=E17:J17+_xlfn.ANCHORARRAY(N17)} -> 1.5173754 | X17: 0.66131337 | Y17: 0.85504526 | Z17: 1.4642025 | AA17: 1.0067184 | AB17: 1.4804822
C18: … | D18: cat | E18: 0.20936074 | F18: 0.82292772 | G18: 0.48358224 | H18: 0.7950404 | I18: 0.4913687 | J18: 0.49423729
C19: … | D19: is | E19: 0.82008295 | F19: 0.14846101 | G19: 0.51524579 | H19: 0.35462162 | I19: 0.80527433 | J19: 0.9058235 | K19: + | T19: =
C20: … | D20: a | E20: 0.30774965 | F20: 0.5079254 | G20: 0.8256578 | H20: 0.73320243 | I20: 0.66711237 | J20: 0.072891681
C21: … | D21: lovely | E21: 0.071914964 | F21: 0.91989941 | G21: 0.38599402 | H21: 0.12314088 | I21: 0.13558803 | J21: 0.9230234
C22: En | D22: cat | E22: 0.57607329 | F22: 0.87735764 | G22: 0.28559611 | H22: 0.82654169 | I22: 0.63669341 | J22: 0.65141078

Sheet -> Inference
B2: INFERENCE, COST FUNCTION
B4: INFERENCE | G4: INFERENCE
G5: Time step 1
I6: FEED FORWARD MATRIX cross matrix
B7: INPUT SEQUENCE | D7: TARGET SEQUENCE | I7: E' cross matrix (output_sequence, vocabsize)
B8: I | D8: <SOS> | I8: <SOS> | J8: amo | K8: <EOS> | L8: molto | M8: … | N8: Ti | O8: Summation | Q8: OUTPUT SEQUENCE
B9: love | D9: Ti | H9: <SOS> | I9: 1 | J9: 0 | K9: 0 | L9: 0 | M9: 0 | N9: 0 | O9: 1
B10: you | D10: amo | G10: C1 | H10: y1 - hat | I10: 0.11 | J10: 0.12 | K10: 0.14 | L10: 0.15 | M10: 0.16 | N10: =0.2+0.12 -> 0.32 | Q10: Ti | S10: 1st logit
B11: so | D11: molto
B12: much | D12: <EOS>
H13: <EOS>
G15: Time step 2
I16: FEED FORWARD MATRIX cross matrix
I17: E' cross matrix (output_sequence, vocabsize)
I18: <SOS> | J18: amo | K18: <EOS> | L18: molto | M18: … | N18: Ti | O18: Summation | Q18: OUTPUT SEQUENCE
H19: <SOS> | I19: 1 | J19: 0 | K19: 0 | L19: 0 | M19: 0 | N19: 0 | O19: 1
G20: C1 | H20: y1 - hat | I20: 0.11 | J20: 0.12 | K20: 0.14 | L20: 0.15 | M20: 0.16 | N20: =0.2+0.12 -> 0.32 | O20: 1 | Q20: Ti | S20: 1st logit
G21: C2 | H21: y2 - hat | I21: 0.1 | J21: 0.6 | K21: 0.1 | L21: 0.1 | M21: 0 | N21: 0.1 | O21: 1 | Q21: amo | S21: 2nd logit
H23: <EOS>
G26: Time step n | I26: …......... Repeats 'til <EOS>
I29: TARGET MATRIX (ONE-HOT)
I30: (output_sequence, vocabsize)
I31: <SOS> | J31: amo | K31: <EOS> | L31: molto | M31: … | N31: Ti | O31: Summation | Q31: OUTPUT SEQUENCE
H32: <SOS> | I32: 1 | J32: 0 | K32: 0 | L32: 0 | M32: 0 | N32: 0 | O32: 1
H33: y1 - true | I33: 0 | J33: 0 | K33: 0 | L33: 0 | M33: 0 | N33: 1 | O33: 1 | Q33: Ti | S33: 1st token
H34: y2 - true | I34: 0 | J34: 1 | K34: 0 | L34: 0 | M34: 0 | N34: 0 | O34: 1 | Q34: amo | S34: 2nd token
H35: y3 - true | I35: 0 | J35: 0 | K35: 0 | L35: 1 | M35: 0 | N35: 0 | O35: 1 | Q35: molto | S35: 3rd token
H36: <EOS> | I36: 0 | J36: 0 | K36: 1 | L36: 0 | M36: 0 | N36: 0 | O36: 1
B37: COST FUNCTION
I39: FEED FORWARD MATRIX cross tensor | R39: TARGET MATRIX (ONE-HOT)
I40: E' cross matrix (output_sequence, vocabsize) | R40: (output_sequence, vocabsize)
I41: <SOS> | J41: amo | K41: <EOS> | L41: molto | M41: … | N41: Ti | R41: <SOS> | S41: amo | T41: <EOS> | U41: molto | V41: … | W41: Ti
H42: <SOS> | I42: 1 | J42: 0 | K42: 0 | L42: 0 | M42: 0 | N42: 0 | Q42: <SOS> | R42: 1 | S42: 0 | T42: 0 | U42: 0 | V42: 0 | W42: 0
H43: y1 - hat | I43: 0.11 | J43: 0.12 | K43: 0.14 | L43: 0.15 | M43: 0.16 | N43: =0.2+0.12 -> 0.32 | Q43: y1 - true | R43: 0 | S43: 0 | T43: 0 | U43: 0 | V43: 0 | W43: 1
H44: y2 - hat | I44: 0.1 | J44: 0.6 | K44: 0.1 | L44: 0.1 | M44: 0 | N44: 0.1 | Q44: y2 - true | R44: 0 | S44: 1 | T44: 0 | U44: 0 | V44: 0 | W44: 0
H45: y3 - hat | I45: 0.1 | J45: 0.1 | K45: 0.1 | L45: 0.5 | M45: 0.1 | N45: 0.1 | Q45: y3 - true | R45: 0 | S45: 0 | T45: 0 | U45: 1 | V45: 0 | W45: 0
H46: <EOS> | I46: 0 | J46: 0 | K46: 1 | L46: 0 | M46: 0 | N46: 0 | O46: each y - data | Q46: <EOS> | R46: 0 | S46: 0 | T46: 1 | U46: 0 | V46: 0 | W46: 0
H50: tokens | I50: P(y1 - hat)
H51: {=TRANSPOSE(I41:N41)} -> <SOS> | I51: {=TRANSPOSE(I43:N43)} -> 0.11
H52: amo | I52: 0.12 | O52: TRAINING (note: Softmax is only applied in INFERENCE!)
...
